WARNING:tensorflow:From /home/aogorodnikov/anaconda3/envs/imgSudoku/lib/python3.7/site-packages/tensorflow/python/framework/op_def_library.py:263: colocate_with (from tensorflow.python.framework.ops) is deprecated and will be removed in a future version.
Instructions for updating:
Colocations handled automatically by placer.
2019-09-21 08:05:44.947401: I tensorflow/core/platform/cpu_feature_guard.cc:141] Your CPU supports instructions that this TensorFlow binary was not compiled to use: SSE4.1 SSE4.2 AVX AVX2 FMA
2019-09-21 08:05:44.992106: I tensorflow/core/platform/profile_utils/cpu_utils.cc:94] CPU Frequency: 2300050000 Hz
2019-09-21 08:05:44.994038: I tensorflow/compiler/xla/service/service.cc:150] XLA service 0x558207d6c670 executing computations on platform Host. Devices:
2019-09-21 08:05:44.994091: I tensorflow/compiler/xla/service/service.cc:158]   StreamExecutor device (0): <undefined>, <undefined>
Autoencoder Architecture
Model: "model_1"
_________________________________________________________________
Layer (type)                 Output Shape              Param #   
=================================================================
input_1 (InputLayer)         (None, 104, 104, 3)       0         
_________________________________________________________________
sequential_1 (Sequential)    (None, 32)                22069760  
_________________________________________________________________
sequential_2 (Sequential)    (None, 104, 104, 3)       22053091  
=================================================================
Total params: 44,122,851
Trainable params: 44,111,843
Non-trainable params: 11,008
_________________________________________________________________
None
Discriminator Architecture
Model: "sequential_3"
_________________________________________________________________
Layer (type)                 Output Shape              Param #   
=================================================================
dense_7 (Dense)              (None, 2704)              89232     
_________________________________________________________________
dense_8 (Dense)              (None, 2704)              7314320   
_________________________________________________________________
dense_9 (Dense)              (None, 1)                 2705      
=================================================================
/home/aogorodnikov/anaconda3/envs/imgSudoku/lib/python3.7/site-packages/keras/engine/training.py:493: UserWarning: Discrepancy between trainable weights and collected trainable weights, did you set `model.trainable` without calling `model.compile` after ?
  'Discrepancy between trainable weights and collected trainable'
Total params: 14,812,514
Trainable params: 7,406,257
Non-trainable params: 7,406,257
_________________________________________________________________
None
Generator Architecture
Model: "model_2"
_________________________________________________________________
Layer (type)                 Output Shape              Param #   
=================================================================
input_2 (InputLayer)         (None, 104, 104, 3)       0         
_________________________________________________________________
sequential_1 (Sequential)    (None, 32)                22069760  
_________________________________________________________________
sequential_3 (Sequential)    (None, 1)                 7406257   
=================================================================
Total params: 29,476,017
Trainable params: 22,058,752
Non-trainable params: 7,417,265
_________________________________________________________________
None
Found 11214 images belonging to 1 classes.
WARNING:tensorflow:From /home/aogorodnikov/anaconda3/envs/imgSudoku/lib/python3.7/site-packages/tensorflow/python/ops/math_ops.py:3066: to_int32 (from tensorflow.python.ops.math_ops) is deprecated and will be removed in a future version.
Instructions for updating:
Use tf.cast instead.
Epoch 1/1
Traceback (most recent call last):
  File "aae.py", line 402, in <module>
    adversarial=argsP.adversarial
  File "aae.py", line 198, in train
    autoencoder_history = autoencoder.fit_generator(train_data, epochs=1)
  File "/home/aogorodnikov/anaconda3/envs/imgSudoku/lib/python3.7/site-packages/keras/legacy/interfaces.py", line 91, in wrapper
    return func(*args, **kwargs)
  File "/home/aogorodnikov/anaconda3/envs/imgSudoku/lib/python3.7/site-packages/keras/engine/training.py", line 1658, in fit_generator
    initial_epoch=initial_epoch)
  File "/home/aogorodnikov/anaconda3/envs/imgSudoku/lib/python3.7/site-packages/keras/engine/training_generator.py", line 181, in fit_generator
    generator_output = next(output_generator)
  File "/home/aogorodnikov/anaconda3/envs/imgSudoku/lib/python3.7/site-packages/keras/utils/data_utils.py", line 616, in get
    six.reraise(*sys.exc_info())
  File "/home/aogorodnikov/anaconda3/envs/imgSudoku/lib/python3.7/site-packages/six.py", line 693, in reraise
    raise value
  File "/home/aogorodnikov/anaconda3/envs/imgSudoku/lib/python3.7/site-packages/keras/utils/data_utils.py", line 603, in get
    inputs = future.get(timeout=30)
  File "/home/aogorodnikov/anaconda3/envs/imgSudoku/lib/python3.7/multiprocessing/pool.py", line 657, in get
    raise self._value
  File "/home/aogorodnikov/anaconda3/envs/imgSudoku/lib/python3.7/multiprocessing/pool.py", line 121, in worker
    result = (True, func(*args, **kwds))
  File "/home/aogorodnikov/anaconda3/envs/imgSudoku/lib/python3.7/site-packages/keras/utils/data_utils.py", line 406, in get_index
    return _SHARED_SEQUENCES[uid][i]
  File "/home/aogorodnikov/anaconda3/envs/imgSudoku/lib/python3.7/site-packages/keras_preprocessing/image/iterator.py", line 65, in __getitem__
    return self._get_batches_of_transformed_samples(index_array)
  File "/home/aogorodnikov/anaconda3/envs/imgSudoku/lib/python3.7/site-packages/keras_preprocessing/image/iterator.py", line 230, in _get_batches_of_transformed_samples
    interpolation=self.interpolation)
  File "/home/aogorodnikov/anaconda3/envs/imgSudoku/lib/python3.7/site-packages/keras_preprocessing/image/utils.py", line 110, in load_img
    img = pil_image.open(path)
  File "/home/aogorodnikov/anaconda3/envs/imgSudoku/lib/python3.7/site-packages/PIL/Image.py", line 2705, in open
    % (filename if filename else fp))
OSError: cannot identify image file '/home/aogorodnikov/data_aae_5k/negative/._Pt11_r02c12_f73_0353.tif'
